ERROR
ERROR
test_0_didsend_more (Identity.test_did.TestDIDSendMore) ... FAIL
test_0_boundary (Identity.test_did_boundary.TestDID) ... ok
test_1_issue_did (Identity.test_did_boundary.TestDID) ... FAIL
test_2_didsend_etp (Identity.test_did_boundary.TestDID) ... FAIL
test_3_didsend_etp_from (Identity.test_did_boundary.TestDID) ... FAIL
test_4_didsend_asset (Identity.test_did_boundary.TestDID) ... ok
test_5_didsend_asset_from (Identity.test_did_boundary.TestDID) ... ok
test_6_modify_did_boundary (Identity.test_did_boundary.TestDID) ... FAIL
test_7_modify_did (Identity.test_did_boundary.TestDID)
modify did between Zac's addresses ... FAIL
test_8_list_didaddresses_boundary (Identity.test_did_boundary.TestDID) ... ok
test_0_didsend_more (Identity.test_did_boundary.TestDIDSendMore) ... ok
test_1_didsend_more (Identity.test_did_boundary.TestDIDSendMore) ... ok
test_0_issuedid (Identity.test_did_multisig.TestDIDMultiSig) ... FAIL
test_1_modifydid (Identity.test_did_multisig.TestDIDMultiSig)
modify did to multisig-address ... FAIL

======================================================================
ERROR: setUpClass (Identity.test_did.TestDIDSend)
----------------------------------------------------------------------
Traceback (most recent call last):
  File "/home/kesalin/projects/metaverse_nova/test/test-rpc/TestCase/Identity/test_did.py", line 15, in setUpClass
    assert (Alice.did_symbol in exist_symbols)
AssertionError

======================================================================
ERROR: setUpClass (Identity.test_did.TestDIDSendAsset)
----------------------------------------------------------------------
Traceback (most recent call last):
  File "/home/kesalin/projects/metaverse_nova/test/test-rpc/TestCase/Identity/test_did.py", line 72, in setUpClass
    assert (Alice.did_symbol in exist_symbols)
AssertionError

======================================================================
FAIL: test_0_didsend_more (Identity.test_did.TestDIDSendMore)
----------------------------------------------------------------------
Traceback (most recent call last):
  File "/home/kesalin/projects/metaverse_nova/test/test-rpc/TestCase/Identity/test_did.py", line 60, in test_0_didsend_more
    self.assertEqual(ec, 0, message)
AssertionError: did ERIC.DID does not exist in blockchain

======================================================================
FAIL: test_1_issue_did (Identity.test_did_boundary.TestDID)
----------------------------------------------------------------------
Traceback (most recent call last):
  File "/home/kesalin/projects/metaverse_nova/test/test-rpc/TestCase/Identity/test_did_boundary.py", line 44, in test_1_issue_did
    self.assertEqual(ec, 0, message)
AssertionError: no enough balance, unspent = 0, payment = 100000000

======================================================================
FAIL: test_2_didsend_etp (Identity.test_did_boundary.TestDID)
----------------------------------------------------------------------
Traceback (most recent call last):
  File "/home/kesalin/projects/metaverse_nova/test/test-rpc/TestCase/Identity/test_did_boundary.py", line 61, in test_2_didsend_etp
    self.assertEqual(ec, 5302, message)
AssertionError: did ALICE.DID does not exist in blockchain

======================================================================
FAIL: test_3_didsend_etp_from (Identity.test_did_boundary.TestDID)
----------------------------------------------------------------------
Traceback (most recent call last):
  File "/home/kesalin/projects/metaverse_nova/test/test-rpc/TestCase/Identity/test_did_boundary.py", line 70, in test_3_didsend_etp_from
    self.assertEqual(ec, 3302, message)
AssertionError: did ALICE.DID does not exist in blockchain

======================================================================
FAIL: test_6_modify_did_boundary (Identity.test_did_boundary.TestDID)
----------------------------------------------------------------------
Traceback (most recent call last):
  File "/home/kesalin/projects/metaverse_nova/test/test-rpc/TestCase/Identity/test_did_boundary.py", line 93, in test_6_modify_did_boundary
    self.assertEqual(ec, 7009, message)
AssertionError: Did 'BOB.DID' does not exist in blockchain

======================================================================
FAIL: test_7_modify_did (Identity.test_did_boundary.TestDID)
modify did between Zac's addresses
----------------------------------------------------------------------
Traceback (most recent call last):
  File "/home/kesalin/projects/metaverse_nova/test/test-rpc/TestCase/Identity/test_did_boundary.py", line 106, in test_7_modify_did
    Alice.send_etp(Zac.mainaddress(), 10**8)
  File "/home/kesalin/projects/metaverse_nova/test/test-rpc/Roles.py", line 120, in send_etp
    assert (result == 0)
AssertionError

======================================================================
FAIL: test_0_issuedid (Identity.test_did_multisig.TestDIDMultiSig)
----------------------------------------------------------------------
Traceback (most recent call last):
  File "/home/kesalin/projects/metaverse_nova/test/test-rpc/TestCase/Identity/test_did_multisig.py", line 15, in test_0_issuedid
    Alice.send_etp(addr, (10 ** 8))
  File "/home/kesalin/projects/metaverse_nova/test/test-rpc/Roles.py", line 120, in send_etp
    assert (result == 0)
AssertionError

======================================================================
FAIL: test_1_modifydid (Identity.test_did_multisig.TestDIDMultiSig)
modify did to multisig-address
----------------------------------------------------------------------
Traceback (most recent call last):
  File "/home/kesalin/projects/metaverse_nova/test/test-rpc/TestCase/Identity/test_did_multisig.py", line 38, in test_1_modifydid
    self.assertEqual(0,1,"function not realized yet.")
AssertionError: function not realized yet.

----------------------------------------------------------------------
Ran 14 tests in 16.957s

FAILED (failures=8, errors=2)
